Workbook

Sheet Introduktion
B3: Konsekvensanalyse vedrørende databeskyttelse til AI-løsninger

Sheet Resume og scope
A1: Resume
A2: [Skriv et kort resume af konsekvensanalysen, fx til ledelsen, herunder vurderingerne, de væsentligste risici og håndteringen heraf.]
A8: Scope
A9: [Beskriv afgrænsningen af, hvilken behandlingsaktivitet der er genstand for konsekvensanalysen. Det kan f.eks. være oplagt, hvis en AI-løsning skal idriftsættes på eksisterende teknisk infrastruktur, at henvise til eksisterende risikovurderinger mv. Konsekvensanalysen omfatter i så fald alene den pågældende AI-løsning.]

Sheet Beskrivelse af aktivitet
A1: ID | B1: Systematisk beskrivelse af behandlingsaktiviteten
A2: Beskrivelse
A3: 1.1 | B3: Formålet med AI-løsningen | I3: [Beskriv overordnet, hvad AI-løsningen skal bruges til, hvilke(n) forretningsproces(ser) løsningen skal understøtte, hvad der ønskes opnået mv. Beskriv, hvilke forretningsproces(ser) og behandlingsaktiviteter der berøres af brugen af AI-løsningen og hvordan.]
A5: 1.2 | B5: Baggrunden for at gennemføre konsekvensanalysen | I5: [Beskriv baggrunden for og vurderingen af, at der skal gennemføres en konsekvensanalyse. Der skal gennemføres en konsekvensanalyse, hvis behandlingsaktiviteten sandsynligvis vil indebære en høj risiko for fysiske personers rettigheder og frihedsrettigheder. Det vil normalt være tilfældet ved udvikling og brug af AI-løsninger.]
A7: Scope og karakter
A8: 1.3 | B8: Baggrunden for at udvikle eller bruge en AI-løsning som led i behandlingsaktiviteten | I8: [Beskriv baggrunden for at udvikle eller implementere AI-løsningen til den pågældende aktivitet. Beskriv (i) typen af løsning, (ii) modelvalg, (iii) designvalg.]
A10: 1.4 | B10: Datastrømme | I10: [Beskriv hvilke persondata der vil blive behandlet som led i udvikling og drift af AI-løsningen: Hvilke type(r) af data behandles? Hvilke typer bruges til henholdsvis (i) udvikling, (ii) test og (iii) drift? Omfatter det særligt beskyttelsesværdige data som fx lokationsdata, økonomiske forhold, sociale forhold eller lignende? Omfatter det særlige kategorier af data eller data om strafbare forhold? Hvor stort er omfanget af data? Hvordan indsamles, bruges og opbevares data og hvor længe? Hvor indsamles data fra? Hvor stammer data fra? Hvilke formål blev data oprindeligt indsamlet til? Hvad er varigheden af behandlingen (isoleret, midlertidig, regelmæssig, vedvarende)?]
A12: 1.5 | B12: Formålsbeskrivelse | I12: [Beskriv hvilke formål data skal bruges til. Hvad ønskes opnået? Hvad er den forventede effekt for de registrerede? Hvad er fordelene for jeres organisation? Hvad er fordelene for samfundet som helhed? Hvilke legitime formål forfølges med databehandlingen?]
A14: 1.6 | B14: Kategorier af registrerede | I14: [Beskriv hvilke kategorier af registrerede data vedrører. Omfatter det børn, patienter, ældre eller andre sårbare grupper? Hvad er antallet af registrerede ved start og på lang sigt?]
A16: 1.7 | B16: Deling af data | I16: [Beskriv om det forventes, at data skal deles med andre. Hvilke modtagere drejer det sig om? Hvordan deles data ned igennem eventuelle leverandørkæder?]
A18: Kontekst
A19: 1.8 | B19: Konteksten for brugen af AI-løsningen | I19: [Beskriv konteksten for brugen af AI-løsningen. Hvordan vil databehandlingen påvirke de berørte personer? Hvad er forholdet til de berørte personer (f.eks. borgere, kunder, medarbejdere mv.)? Hvor meget kontrol vil de berørte personer have? Hvad er de berørte personers berettigede forventninger med hensyn til behandling af deres persondata? Er der særlige udtalte bekymringer, f.eks. blandt de berørte personer eller i offentligheden, som bør indregnes?]
A21: Aktiver
A22: 1.9 | B22: Teknisk understøttelse | I22: [Beskriv i relevant omfang den tekniske understøttelse af AI-løsningen, herunder f.eks hardware, software, øvrige aktiver mv.]

Sheet Vurdering af lovlighed
A1: ID | B1: Vurdering af lovlighed
A2: Relevant forpligtelse | I2: Vurdering
A3: Afgrænsning og use case
A4: 2.1 | B4: Princippet om lovlighed Artikel 5, stk. 1, litra a, artikel 6, stk. 1, og præambelbetragtning nr. 39, 40 samt 58 | I4: [Beskriv vurderingen af, hvilket behandlingsgrundlag der muliggør behandling af personoplysninger til såvel udvikling som drift af AI-løsningen. Beskriv vurderingen seperat for udvikling og for drift af løsningen. Hvis drift af AI-løsningen understøtter eller berører flere forretningsprocesser eller behandlingsaktiviteter, beskriv da behandlingsgrundlaget særskilt for de pågældende behandlingsaktiviteter.]
A6: 2.2 | B6: Relevant undtagelse for behandling af særlige kategorier af personoplysninger Artikel 9, stk. 2, og præambelbetragtning nr. 52-56 | I6: [Beskriv, hvis relevant, vurderingen af, hvilken undtagelse til det generelle forbud mod behandling af særlige kategorier af oplysninger der muliggør behandling af sådanne kategorier til såvel udvikling som drift af AI-løsningen. Beskriv vurderingen seperat for udvikling og for drift af løsningen.]
A8: 2.3 | B8: Behandling af oplysninger om strafbare forhold Databeskyttelseslovens § 8 | I8: [Beskriv, hvis relevant, vurderingen af, hvilket behandllingsgrundlag der muliggør behandling af oplysninger om strafbare forhold til såvel udvikling som drift af AI-løsningen. Beskriv vurderingen seperat for udvikling og for drift af løsningen.]
A10: 2.4 | B10: Behandling af oplysninger om personnummer (CPR) Databeskyttelseslovens § 11 | I10: [Beskriv, hvis relevant, vurderingen af, hvilket behandllingsgrundlag der muliggør behandling af oplysninger om personnummer til såvel udvikling som drift af AI-løsningen. Beskriv vurderingen seperat for udvikling og for drift af løsningen.]
A12: 2.5 | B12: Princippet om rimelighed Artikel 5, stk. 1, litra a, og præambelbetragtning nr. 39, 40 samt 58 | I12: [Beskriv hvilke udfordringer eller problemstillinger den påtænkte brug af AI-løsningen skal adressere, og hvilke konkrete målsætninger brugen af løsningen har. Hvis der på dette tidlige stadie er klarhed over, hvilke problemstillinger AI-løsningen skal adressere og hvordan, er det lettere at vurdere, om løsningens output indebærer urimelige udfald for de registrerede.]
A14: 2.6 | B14: Princippet om gennemsigtighed Artikel 5, stk. 1, litra a, og præambelbetragtning nr. 39, 58 samt 60 | I14: [Beskriv vurderingen af, i hvilket omfang valg af model og designvalg understøtter evnen til at fortolke og forklare AI-løsningens output]
A16: 2.7 | B16: Princippet om formålsbegrænsning Artikel 5, stk. 1, litra b, og præambelbetragtning nr. 39 og 50 | I16: [Beskriv vurderingen af, i hvilket omfang formålet med behandling af personoplysninger ved udvikling og drift af AI-løsningen er sagligt og specifikt. Beskriv i hvilket omfang brug af de påtænkte datasæt til træning og test er foreneligt med det formål, som data oprindeligt er indsamlet til.]
A18: 2.8 | B18: Proportionalitetsprincippet Artikel 5, stk. 1, litra c, og præambelbetragtning nr. 39 | I18: [Beskriv i hvilket omfang behandling af persondata ved udvikling og drift af AI-løsningen er egnet, nødvendig og forholdsmæssig. - Beskriv afvejningen mellem det overordnede hensyn til de registrerede over for de hensyn, der taler for at udvikle og bruge AI-løsningen. - Beskriv hvordan AI-løsningen udvikles, trænes og drives ved brug af færrest muligt oplysninger, om om muligt uden persondata. - Beskriv hvilke privatlivsfremmende teknologier der er blevet overvejet for at minimere mængden af persondata til udvikling, f.eks. fødereret læring eller syntetiske data]
A20: 2.9 | B20: Princippet om rigtighed Artikel 5, stk. 1, litra d, og præambelbetragtning nr. 39 | I20: [Beskriv i hvilket omfang det er passende at bruge AI-løsningen i den pågældende sammenhæng i lyset af løsningens mulighed for og evne til at give korrekte og retvisende svar.]
A22: 2.10 | B22: Princippet om opbevaringsbegrænsning Artikel 5, stk. 1, litra e, og præambelbetragtning nr. 39 | I22: [Beskriv vurderingen af, hvor længe det er nødvendigt at opbevare trænings- og testdatasæt, samt hvordan det sikres, at data slettes efter udløbet af perioden]
A24: Udvikling og test
A25: 2.11 | B25: Princippet om lovlighed Artikel 5, stk. 1, litra a, og præambelbetragtning nr. 39, 40 samt 58 | I25: [Beskriv hvordan det sikres, at der i trænings- og testdata ikke indgår data, som er resultatet af brud på persondatasikkerheden eller i øvrigt er ulovligt tilvejebragt.]
A27: 2.12 | B27: Princippet om rimelighed Artikel 5, stk. 1, litra a, og præambelbetragtning nr. 39, 40 samt 58 | I27: [Beskriv hvordan det sikres, at træningsdata er retvisende, repræsentativt, og at eventuel tidligere bias håndteres. Beskriv hvordan det igennem model- og designvalg sikres, at AI-løsningen ikke genererer urimelige output eller resulterer i ulovlig forskelsbehandling.]
A29: 2.13 | B29: Princippet om gennemsigtighed Artikel 5, stk. 1, litra a, og præambelbetragtning nr. 39, 58 samt 60 | I29: [Beskriv hvordan det sikres gennem model- og designvalg samt implementering af foranstaltninger i øvrigt, at AI-løsningens output kan forklares.]
A31: 2.14 | B31: Proportionalitetsprincippet Artikel 5, stk. 1, litra c, og præambelbetragtning nr. 39 | I31: [Beskriv hvordan det sikres, at mængden af trænings- og testdata er begrænset til det nødvendige, og at der i det enkelte datasæt ikke indgår datapunkter, som ikke er nødvendige til træning og test.]
A33: 2.15 | B33: Princippet om rigtighed Artikel 5, stk. 1, litra d, og præambelbetragtning nr. 39 | I33: [Beskriv hvordan det sikres, at trænings- og testdata er korrekte og retvisende.]
A35: Drift
A36: 2.16 | B36: Princippet om rimelighed Artikel 5, stk. 1, litra a, og præambelbetragtning nr. 39, 58 samt 60 | I36: [Beskriv hvordan det sikres, at AI-løsningen i drift ikke genererer urimelige output, f.eks. ved løbende overvågning og test, og hvordan eventuel bias i output opdages og håndteres.]
A38: 2.17 | B38: Princippet om gennemsigtighed Artikel 5, stk. 1, litra a, og præambelbetragtning nr. 39, 58 samt 60 | I38: [Beskriv hvordan det sikres, at output kan forklares, f.eks. hvis output danner grundlag for en beslutning over for den registrerede.]
A40: 2.18 | B40: Proportionalitetsprincippet Artikel 5, stk. 1, litra c, og præambelbetragtning nr. 39 | I40: [Beskriv hvordan det sikres, at input er begrænset til det nødvendige og relevante, og at der ikke indgår unødvendige data.]
A42: 2.19 | B42: Princippet om rigtighed Artikel 5, stk. 1, litra d, og præambelbetragtning nr. 39 | I42: [Beskriv hvordan det sikres, at AI-løsningen fortsat genererer korrekte og retvisende output, f.eks. hvordan løbende modeldrift opdages og afhjælpes, hvordan statiske modeller overvåges og om nødvendigt gentrænes mv.]
A44: Hele livscyklus – Behandlingssikkerhed
A45: 2.20 | B45: Princippet om integritet og fortrolighed samt behandlingssikkerhed Artikel 5, stk. 1, litra f, og artikel 32-34 samt præambelbetragtning nr. 75, 76, 83 og 85-88 | I45: [Beskriv hvordan behandlingssikkerheden sikres igennem hele løsningens livscyklus, f.eks. ved gennemførte risikovurderinger og implementerede sikkerhedsforanstaltninger. Kan med fordel beskrives i bilag.]
A47: 2.21 | B47: Brud på persondatasikkerheden Artikel 5, stk. 1, litra f, og artikel 33-34 samt præambelbetragtning nr. 75, 76, 83 og 85-88 | I47: [Beskriv, hvordan brud på persondatasikkerheden håndteres, og hvordan de registrerede eventuelt underrettes om brud, som sandsynligvis vil indebære en høj risiko for de pågældende.]
A49: Hele livscyklus – Registreredes rettigheder
A50: 2.22 | B50: Oplysningspligt Databeskyttelsesforordningens artikel 12-14 samt præambelbetragtning nr. 60-62 | I50: [Beskriv hvordan oplysningspligten iagttages over for de registrede både ved udvikling og i drift, herunder om der gives meningsfulde oplysninger om logikken i AI-løsningen og de forventede konsekvenser, hvis relevant.]
A52: 2.23 | B52: Indsigtsret Databeskyttelsesforordningens artikel 15 samt præambelbetragtning nr. 63-64 | I52: [Beskriv hvordan det sikres, at anmodninger om indsigt håndteres korrekt, herunder om der kan gives meningsfulde oplysninger om logikken i AI-løsningen og de forventede konsekvenser, hvis relevant.]
A54: 2.24 | B54: Retten til berigtigelse Databeskyttelsesforordningens artikel 16 samt præambelbetragtning nr. 65 | I54: [Beskriv hvordan det sikres, at anmodninger om berigtigelse håndteres korrekt, herunder om de registrerede kan få berigtiget eventuelle træningsdata eller få berigtiget løsningens output, samt hvordan underretning af eventuelle modtagere af ukorrekte oplysninger kan ske.]
A56: 2.25 | B56: Retten til sletning Databeskyttelsesforordningens artikel 17 samt præambelbetragtning nr. 65 | I56: [Beskriv hvordan det sikres, at anmodninger om sletning håndteres korrekt, herunder om de registrerede kan få slettet eventuelle oplysninger i træningsdata eller i output, samt hvordan underretning af eventuelle modtagere af oplysninger, der skal slettes, kan ske.]
A58: 2.26 | B58: Retten til dataportabilitet Databeskyttelsesforordningens artikel 20 samt præambelbetragtning nr. 68 | I58: [Beskriv, hvis det er relevant, hvordan det sikres, at anmodninger om dataportabilitet håndteres korrekt.]
A60: 2.27 | B60: Ret til at gøre indsigelse Databeskyttelsesforordningens artikel 21 samt præambelbetragtning nr. 69 | I60: [Beskriv, hvis det er relevant, hvordan det sikres, at de registrerede har ret til at gøre indsigelse med hensyn til brug af vedkommendes data til udvikling af løsningen, eller mod at oplysningerne bruges som input.]
A62: 2.28 | B62: Ret til ikke at være genstand for automatiske indviduelle afgørelser Databeskyttelsesforordningens artikel 22 samt præambelbetragtning nr. 71 | I62: [Beskriv, hvis det er relevant, hvordan det sikres, at de registrerede har ret til menneskelig indgriben med hensyn til AI-løsningens output, kan fremkomme med sine synspunkter og bestride afgørelsen.]
A64: Hele livscyklus – Brug af databehandlere
A65: 2.29 | B65: Databehandlere Artikel 28 samt præambelbetragtning nr. 81 | I65: [Beskriv, hvis det er relevant, hvilke databehandlere der benyttes som led i udvikling og drift af AI-løsningen, hvilken behandling der foretages af disse, samt hvilke fornødne garantier databehandlerne har givet for, at behandlingen sker i overensstemmelse med databeskyttelsesreglerne. Kan med fordel beskrives i bilag.]
A67: Hele livscyklus – Tredjelandsoverførsler
A68: 2.30 | B68: Tredjelandsoverførsler Artikel 44-49 samt præambelbetragtning nr. 101-115 | I68: [Beskriv, hvis det er relevant, hvilke tredjelande personoplysninger overføres til som led i udvikling og drift af AI-løsningen, hvilket overførselsgrundlag der anvendes, samt I hvilket omfang overførselsgrundlaget er effektivt. Kan med fordel beskrives i bilag.]

Sheet Evalueringskriterier
B2: Evalueringskriterier for sandsynlighed og konsekvens
I4: Kriterier for evaluering af sandsynlighed | M4: Kriterier for evaluering af konsekvens | Q4: Risikomatrix
I5: # | J5: SANDSYNLIGHED | K5: BESKRIVELSE | M5: # | N5: KONSEKVENS | O5: BESKRIVELSE | Q5: =N9 -> Ødelæggende (4) | R5: Høj | S5: Meget høj | T5: Meget høj | U5: Meget høj
I6: 1 | J6: Usandsynligt (1) | K6: Det kan anses for næsten udelukket, at hændelsen nogensinde kan forekomme; fx (i) Ingen erfaring med hændelsen; eller (ii) Kendes kun fra få og af hinanden uafhængige hændelser i offentlige og private virksomheder | M6: 1 | N6: Ubetydelig (1) | O6: Registrerede kan opleve få uhensigtsmæssigheder, der kan overkommes og imødegås uden større indsats (tid brugt på at genindtaste oplysninger, dårlig brugeroplevelse, irritation og lignende). | Q6: =N8 -> Meget alvorlig (3) | R6: Mellem | S6: Høj | T6: Høj | U6: Meget høj
I7: 2 | J7: Mindre sandsynligt (2) | K7: Hændelsen forventes ikke at forekomme; fx (i) Mindre erfraring med hændelsen; eller (ii) Kendes fra offentlige og private virksomheder | M7: 2 | N7: Mindre alvorlig (2) | O7: Registrerede kan opleve betydelige uhensigtsmæssigheder, som de kan overkomme med en indsats og overvindelse af nogle få besværligheder (ekstra omkostninger, manglende adgang til forretningsservices, frygt, mangel på forståelse, stress og mindre påvirkning af fysisk karakter og lignende). | Q7: =N7 -> Mindre alvorlig (2) | R7: Lav | S7: Mellem | T7: Høj | U7: Høj
I8: 3 | J8: Sandsynligt (3) | K8: Det er sandsynligt, at hændelsen vil forekomme; fx (i) Man har erfaring med hændelsen, men ikke inden for de seneste 12 måneder; eller (ii) Kendes fra offentlige og private virksomheder (omtales årligt i pressen) | M8: 3 | N8: Meget alvorlig (3) | O8: Registrerede kan opleve betydelige konsekvenser, som kun kan overkommes med betydelig indsats og konsekvenser for den enkelte (økonomiske konsekvenser, fejlkontering af midler, sortlistning eller nedgradering i kreditmuligheder, fysisk skade på aktiver, påvirkning af arbejdssituation, stævning, dårligere helbred og lignende). | Q8: =N6 -> Ubetydelig (1) | R8: Lav | S8: Lav | T8: Mellem | U8: Høj
I9: 4 | J9: Forventet (4) | K9: Det forventes, at hændelsen vil forekomme; fx (i) Man har erfaring med hændelsen inden for de sidste 12 måneder; eller (ii) Hænder jævnligt i andre offentlige og private organisationer (omtales ofte i pressen) | M9: 4 | N9: Ødelæggende (4) | O9: Registrerede kan opleve betydelige og indgribende konsekvenser, som det ikke er muligt eller kun vanskeligt muligt at overkomme (mistet erhvervsevne, langvarige fysiske og psykiske påvirkninger, død og lignende). | R9: =J6 -> Usandsynligt (1) | S9: =J7 -> Mindre sandsynligt (2) | T9: =J8 -> Sandsynligt (3) | U9: =J9 -> Forventet (4)

Sheet Risici
A1: AI's livscyklus | B1: ID | C1: Risikoområde | D1: Overordnet reskrivelse af risiko | E1: Konkret risikoscenarie | F1: Sandsynlighed for indtræden | G1: Alvorligste mulige konsekvenser for de registrerede | H1: Konsekvens ved indtræden | I1: Iboende risiko | J1: Mitigerende foranstaltning(er) | K1: Sandsynlighed for indtræden (efter mitigering) | L1: Konsekvens ved indtræden (efter mitigering) | M1: Residualrisiko (efter mitigering) | N1: Risikoejer | O1: Implementeringsstatus | P1: Gennemførelsesdato
A2: Afgrænsning af business og use case
A3: Afgrænsning af business og use case | B3: 3.1 | C3: Ansvarlighed Artikel 5, stk. 2, 35 og 36 samt betragtning nr. 74-77, 84, 89-92, 94 og 95. | D3: Manglende eller mangelfuld identifikation og mitigering af risiciene for de registrerede. | F3: Forventet (4) | H3: Ødelæggende (4) | I3: =INDEX(Evalueringskriterier!$R$5:$U$8,MATCH(H3,Evalueringskriterier!$Q$5:$Q$8,0),MATCH(F3,Evalueringskriterier!$R$9:$U$9,0)) -> Meget høj | K3: Forventet (4) | L3: Ødelæggende (4) | M3: =INDEX(Evalueringskriterier!$R$5:$U$8,MATCH(L3,Evalueringskriterier!$Q$5:$Q$8,0),MATCH(K3,Evalueringskriterier!$R$9:$U$9,0)) -> Meget høj
A4: Afgrænsning af business og use case | B4: 3.2 | C4: Ansvarlighed Artikel 5, stk. 2, og 24 samt betragtning nr. 39 and 74 | D4: Mangelfuld rolle- og ansvarsfordeling, der fører til, at ingen personer i organisationen har ejerskab over de risici, der følger af brugen af AI. Det kan medføre, at risiciene ikke adresseres eller ikke adresseres rettidigt med konsekvenser for de registrerede til følge. | F4: Forventet (4) | H4: Ødelæggende (4) | I4: =INDEX(Evalueringskriterier!$R$5:$U$8,MATCH(H4,Evalueringskriterier!$Q$5:$Q$8,0),MATCH(F4,Evalueringskriterier!$R$9:$U$9,0)) -> Meget høj | K4: Forventet (4) | L4: Ødelæggende (4) | M4: =INDEX(Evalueringskriterier!$R$5:$U$8,MATCH(L4,Evalueringskriterier!$Q$5:$Q$8,0),MATCH(K4,Evalueringskriterier!$R$9:$U$9,0)) -> Meget høj
A5: Afgrænsning af business og use case | B5: 3.3 | C5: Formålsbegrænsning og lovlighed Artikel 5, stk. 1, litra b, artikel 6, stk. 1 og 4, og 30 samt betragtning nr. 39 og 50. | D5: Scope creep som følge af manglende klarhed over, hvilke(t) formål AI-løsningen skal bruges til, eller ulovlig behandling som følge af manglende kendskab til kilden til trænings-, test- eller inputdata. | F5: Forventet (4) | H5: Ødelæggende (4) | I5: =INDEX(Evalueringskriterier!$R$5:$U$8,MATCH(H5,Evalueringskriterier!$Q$5:$Q$8,0),MATCH(F5,Evalueringskriterier!$R$9:$U$9,0)) -> Meget høj | K5: Forventet (4) | L5: Ødelæggende (4) | M5: =INDEX(Evalueringskriterier!$R$5:$U$8,MATCH(L5,Evalueringskriterier!$Q$5:$Q$8,0),MATCH(K5,Evalueringskriterier!$R$9:$U$9,0)) -> Meget høj
A6: Afgrænsning af business og use case | B6: 3.4 | C6: Princippet om rimelighed Artikel 5, stk. 1, litra a, og præambelbetragtning nr. 39, 40 samt 58 | D6: Urimelige eller diskriminerende udfald for de registrerede som følge af, at træningsdata er (i) utilstrækkelig forskelligartet, (ii) uegnet til formålet eller (iii) afspejler tidligere bias. Det kan også ske som følge af designvalg eller andre årsag. | F6: Forventet (4) | H6: Ødelæggende (4) | I6: =INDEX(Evalueringskriterier!$R$5:$U$8,MATCH(H6,Evalueringskriterier!$Q$5:$Q$8,0),MATCH(F6,Evalueringskriterier!$R$9:$U$9,0)) -> Meget høj | K6: Forventet (4) | L6: Ødelæggende (4) | M6: =INDEX(Evalueringskriterier!$R$5:$U$8,MATCH(L6,Evalueringskriterier!$Q$5:$Q$8,0),MATCH(K6,Evalueringskriterier!$R$9:$U$9,0)) -> Meget høj
A7: Afgrænsning af business og use case | B7: 3.5 | C7: Gennemsigtighed Artikel 5, stk. 1, litra a, og 12-15 samt præambelbetragtning nr. 60-62 | D7: Manglende gennemsigtighed eller manglende evne til at fortolke eller forklare AI-løsningens output som følge af valg i design og udvikling af løsningen. Det kan føre til, at de registrerede ikke forstår, hvordan deres oplysninger behandles, hvordan AI-løsningen kan påvirke dem, og hvordan de kan udøve deres rettigheder. | F7: Forventet (4) | H7: Ødelæggende (4) | I7: =INDEX(Evalueringskriterier!$R$5:$U$8,MATCH(H7,Evalueringskriterier!$Q$5:$Q$8,0),MATCH(F7,Evalueringskriterier!$R$9:$U$9,0)) -> Meget høj | K7: Forventet (4) | L7: Ødelæggende (4) | M7: =INDEX(Evalueringskriterier!$R$5:$U$8,MATCH(L7,Evalueringskriterier!$Q$5:$Q$8,0),MATCH(K7,Evalueringskriterier!$R$9:$U$9,0)) -> Meget høj
A8: Afgrænsning af business og use case | B8: 3.6 | C8: Dataminimering Artikel 5, stk. 1, litra c, samt betragtning nr. 39 | D8: Indsamling af overflødige og/eller irrelevante data som følge af en standardiseret tilgang om at indsamle mest muligt data for at udvikle og drifte AI-løsninger. | F8: Forventet (4) | H8: Ødelæggende (4) | I8: =INDEX(Evalueringskriterier!$R$5:$U$8,MATCH(H8,Evalueringskriterier!$Q$5:$Q$8,0),MATCH(F8,Evalueringskriterier!$R$9:$U$9,0)) -> Meget høj | K8: Forventet (4) | L8: Ødelæggende (4) | M8: =INDEX(Evalueringskriterier!$R$5:$U$8,MATCH(L8,Evalueringskriterier!$Q$5:$Q$8,0),MATCH(K8,Evalueringskriterier!$R$9:$U$9,0)) -> Meget høj
A9: Afgrænsning af business og use case | B9: 3.7 | C9: Sikkerhed Artikel 5, stk. 1, litra f, og artikel 32-34 samt præambelbetragtning nr. 83 og 85-88 | D9: Utilsigtet adgang til AI-løsningen eller læk af persondata som følge af, at udvikling af AI-løsning skal ske ved brug af tredjepartsmodeller, som er inficeret med ondsindet kode. | F9: Forventet (4) | H9: Ødelæggende (4) | I9: =INDEX(Evalueringskriterier!$R$5:$U$8,MATCH(H9,Evalueringskriterier!$Q$5:$Q$8,0),MATCH(F9,Evalueringskriterier!$R$9:$U$9,0)) -> Meget høj | K9: Forventet (4) | L9: Ødelæggende (4) | M9: =INDEX(Evalueringskriterier!$R$5:$U$8,MATCH(L9,Evalueringskriterier!$Q$5:$Q$8,0),MATCH(K9,Evalueringskriterier!$R$9:$U$9,0)) -> Meget høj
A10: Afgrænsning af business og use case | B10: 3.8 | C10: Rettigheder Artikel 15-22 og præambelbetragtning nr. 60-71 | D10: Manglende evne til at håndtere anmodninger fra de registrerede om at udøve deres rettigheder som følge af manglende opmærksomhed på de registreredes rettigheder igennem hele AI-løsningens livscyklus. | F10: Forventet (4) | H10: Ødelæggende (4) | I10: =INDEX(Evalueringskriterier!$R$5:$U$8,MATCH(H10,Evalueringskriterier!$Q$5:$Q$8,0),MATCH(F10,Evalueringskriterier!$R$9:$U$9,0)) -> Meget høj | K10: Forventet (4) | L10: Ødelæggende (4) | M10: =INDEX(Evalueringskriterier!$R$5:$U$8,MATCH(L10,Evalueringskriterier!$Q$5:$Q$8,0),MATCH(K10,Evalueringskriterier!$R$9:$U$9,0)) -> Meget høj
A11: Udvikling
A12: Udvikling | B12: 4.1 | C12: Rimelighed Artikel 5, stk. 1, litra a, og præambelbetragtning nr. 39, 58 samt 60 | D12: AI-løsninger medfører urimelige udfald for de registrerede som følge af, at træningsdata er (i) utilstrækkelig forskelligartet, (ii) uegnet til formålet, eller som (iii) afspejler tidligere bias, eller som følge af (iv) designvalg eller anden årsag. Som følge heraf kan de registrerede blive påvirket negativt, f.eks. ved diskrimination, finansielle tab eller sociale ulemper. | F12: Forventet (4) | H12: Ødelæggende (4) | I12: =INDEX(Evalueringskriterier!$R$5:$U$8,MATCH(H12,Evalueringskriterier!$Q$5:$Q$8,0),MATCH(F12,Evalueringskriterier!$R$9:$U$9,0)) -> Meget høj | K12: Forventet (4) | L12: Ødelæggende (4) | M12: =INDEX(Evalueringskriterier!$R$5:$U$8,MATCH(L12,Evalueringskriterier!$Q$5:$Q$8,0),MATCH(K12,Evalueringskriterier!$R$9:$U$9,0)) -> Meget høj
A13: Udvikling | B13: 4.2 | C13: Rimelighed Artikel 5, stk. 1, litra a, og præambelbetragtning nr. 39, 58 samt 60 | D13: Diskriminerende udfald som følge af, at AI-løsningen lægger vægt på features, der fører til direkte eller indirekte diskrimination, som led i en beslutning eller en afgørelse. | F13: Forventet (4) | H13: Ødelæggende (4) | I13: =INDEX(Evalueringskriterier!$R$5:$U$8,MATCH(H13,Evalueringskriterier!$Q$5:$Q$8,0),MATCH(F13,Evalueringskriterier!$R$9:$U$9,0)) -> Meget høj | K13: Forventet (4) | L13: Ødelæggende (4) | M13: =INDEX(Evalueringskriterier!$R$5:$U$8,MATCH(L13,Evalueringskriterier!$Q$5:$Q$8,0),MATCH(K13,Evalueringskriterier!$R$9:$U$9,0)) -> Meget høj
A14: Udvikling | B14: 4.3 | C14: Rimelighed Artikel 5, stk. 1, litra a, og præambelbetragtning nr. 39, 58 samt 60 | D14: Mangelfuld mærkning af træningsdata, der skyldes uklare politikker eller procedurer. | F14: Forventet (4) | H14: Ødelæggende (4) | I14: =INDEX(Evalueringskriterier!$R$5:$U$8,MATCH(H14,Evalueringskriterier!$Q$5:$Q$8,0),MATCH(F14,Evalueringskriterier!$R$9:$U$9,0)) -> Meget høj | K14: Forventet (4) | L14: Ødelæggende (4) | M14: =INDEX(Evalueringskriterier!$R$5:$U$8,MATCH(L14,Evalueringskriterier!$Q$5:$Q$8,0),MATCH(K14,Evalueringskriterier!$R$9:$U$9,0)) -> Meget høj
A15: Udvikling | B15: 4.4 | C15: Rimelighed Artikel 5, stk. 1, litra a og c, og præambelbetragtning nr. 39, 58 samt 60 | D15: Utilstrækkelige træningsdata, som fører til overfitting som følge af, at der ikke indsamles nok features eller data. | F15: Forventet (4) | H15: Ødelæggende (4) | I15: =INDEX(Evalueringskriterier!$R$5:$U$8,MATCH(H15,Evalueringskriterier!$Q$5:$Q$8,0),MATCH(F15,Evalueringskriterier!$R$9:$U$9,0)) -> Meget høj | K15: Forventet (4) | L15: Ødelæggende (4) | M15: =INDEX(Evalueringskriterier!$R$5:$U$8,MATCH(L15,Evalueringskriterier!$Q$5:$Q$8,0),MATCH(K15,Evalueringskriterier!$R$9:$U$9,0)) -> Meget høj
A16: Udvikling | B16: 4.5 | C16: Gennemsigtighed Artikel 5, stk. 1, litra a, og 12-15 samt præambelbetragtning nr. 60-62 | D16: Uklar privatlivspolitik eller informationsmeddelelse som følge af manglende afklaring af, hvilket formål AI-løsningen vil blive brugt til. | F16: Forventet (4) | H16: Ødelæggende (4) | I16: =INDEX(Evalueringskriterier!$R$5:$U$8,MATCH(H16,Evalueringskriterier!$Q$5:$Q$8,0),MATCH(F16,Evalueringskriterier!$R$9:$U$9,0)) -> Meget høj | K16: Forventet (4) | L16: Ødelæggende (4) | M16: =INDEX(Evalueringskriterier!$R$5:$U$8,MATCH(L16,Evalueringskriterier!$Q$5:$Q$8,0),MATCH(K16,Evalueringskriterier!$R$9:$U$9,0)) -> Meget høj
A17: Udvikling | B17: 4.6 | C17: Dataminimering Artikel 5, stk. 1, litra c, og betragtning nr. 39 | D17: Indsamling af overskydende personoplysninger som følge af manglende anvendelse af anonymiseringsteknikker. | F17: Forventet (4) | H17: Ødelæggende (4) | I17: =INDEX(Evalueringskriterier!$R$5:$U$8,MATCH(H17,Evalueringskriterier!$Q$5:$Q$8,0),MATCH(F17,Evalueringskriterier!$R$9:$U$9,0)) -> Meget høj | K17: Forventet (4) | L17: Ødelæggende (4) | M17: =INDEX(Evalueringskriterier!$R$5:$U$8,MATCH(L17,Evalueringskriterier!$Q$5:$Q$8,0),MATCH(K17,Evalueringskriterier!$R$9:$U$9,0)) -> Meget høj
A18: Udvikling | B18: 4.7 | C18: Sikkerhed Artikel 5, stk. 1, litra f, og artikel 32-34 samt præambelbetragtning nr. 83 og 85-88 | D18: Utilsigtet adgang til og manipulation af træningsdata og/eller kildekode | F18: Forventet (4) | H18: Ødelæggende (4) | I18: =INDEX(Evalueringskriterier!$R$5:$U$8,MATCH(H18,Evalueringskriterier!$Q$5:$Q$8,0),MATCH(F18,Evalueringskriterier!$R$9:$U$9,0)) -> Meget høj | K18: Forventet (4) | L18: Ødelæggende (4) | M18: =INDEX(Evalueringskriterier!$R$5:$U$8,MATCH(L18,Evalueringskriterier!$Q$5:$Q$8,0),MATCH(K18,Evalueringskriterier!$R$9:$U$9,0)) -> Meget høj
A19: Udvikling | B19: 4.8 | C19: Sikkerhed Artikel 5, stk. 1, litra f, og artikel 32-34 samt præambelbetragtning nr. 83 og 85-88 | D19: Svagheder i forsyningskæden, f.eks. som følge af ondsindet kode i kodebiblioteker eller brug af forældede kodebiblioteker, eller som følge af manglende eller mangelfuld håndtering af plug-ins og integrationer til øvrige systemer. | F19: Forventet (4) | H19: Ødelæggende (4) | I19: =INDEX(Evalueringskriterier!$R$5:$U$8,MATCH(H19,Evalueringskriterier!$Q$5:$Q$8,0),MATCH(F19,Evalueringskriterier!$R$9:$U$9,0)) -> Meget høj | K19: Forventet (4) | L19: Ødelæggende (4) | M19: =INDEX(Evalueringskriterier!$R$5:$U$8,MATCH(L19,Evalueringskriterier!$Q$5:$Q$8,0),MATCH(K19,Evalueringskriterier!$R$9:$U$9,0)) -> Meget høj
A20: Test
A21: Test | B21: 5.1 | C21: Rimelighed Artikel 5, stk. 1, litra a, og præambelbetragtning nr. 39, 58 samt 60 | D21: Overfitting som følge af, at modellen tillægger specifikke features i træningsdata for stor betydning. | F21: Forventet (4) | H21: Ødelæggende (4) | I21: =INDEX(Evalueringskriterier!$R$5:$U$8,MATCH(H21,Evalueringskriterier!$Q$5:$Q$8,0),MATCH(F21,Evalueringskriterier!$R$9:$U$9,0)) -> Meget høj | K21: Forventet (4) | L21: Ødelæggende (4) | M21: =INDEX(Evalueringskriterier!$R$5:$U$8,MATCH(L21,Evalueringskriterier!$Q$5:$Q$8,0),MATCH(K21,Evalueringskriterier!$R$9:$U$9,0)) -> Meget høj
A22: Test | B22: 5.2 | C22: Rimelighed Artikel 5, stk. 1, litra a, og præambelbetragtning nr. 39, 58 samt 60 | D22: Diskriminerende udfald som følge af, at AI-løsningen lægger vægt på features, som fører til direkte eller indirekte diskrimination, som led i en beslutning eller en afgørelse. | F22: Forventet (4) | H22: Ødelæggende (4) | I22: =INDEX(Evalueringskriterier!$R$5:$U$8,MATCH(H22,Evalueringskriterier!$Q$5:$Q$8,0),MATCH(F22,Evalueringskriterier!$R$9:$U$9,0)) -> Meget høj | K22: Forventet (4) | L22: Ødelæggende (4) | M22: =INDEX(Evalueringskriterier!$R$5:$U$8,MATCH(L22,Evalueringskriterier!$Q$5:$Q$8,0),MATCH(K22,Evalueringskriterier!$R$9:$U$9,0)) -> Meget høj
A23: Test | B23: 5.3 | C23: Gennemsigtighed Artikel 5, stk. 1, litra a, og 12-15 samt præambelbetragtning nr. 60-62 | D23: Registrerede bliver genstand for uforklarlige afgørelser eller beslutninger fra AI-løsninger, der drives af komplekse algoritmer (black box). | F23: Forventet (4) | H23: Ødelæggende (4) | I23: =INDEX(Evalueringskriterier!$R$5:$U$8,MATCH(H23,Evalueringskriterier!$Q$5:$Q$8,0),MATCH(F23,Evalueringskriterier!$R$9:$U$9,0)) -> Meget høj | K23: Forventet (4) | L23: Ødelæggende (4) | M23: =INDEX(Evalueringskriterier!$R$5:$U$8,MATCH(L23,Evalueringskriterier!$Q$5:$Q$8,0),MATCH(K23,Evalueringskriterier!$R$9:$U$9,0)) -> Meget høj
A24: Test | B24: 5.4 | C24: Rigtighed Artikel 5, stk. 1, litra d, og betragtning nr. 39 | D24: Forkert output som følge af, at AI-løsningen er udviklet ved brug af ufuldstændige eller forkerte data. | F24: Forventet (4) | H24: Ødelæggende (4) | I24: =INDEX(Evalueringskriterier!$R$5:$U$8,MATCH(H24,Evalueringskriterier!$Q$5:$Q$8,0),MATCH(F24,Evalueringskriterier!$R$9:$U$9,0)) -> Meget høj | K24: Forventet (4) | L24: Ødelæggende (4) | M24: =INDEX(Evalueringskriterier!$R$5:$U$8,MATCH(L24,Evalueringskriterier!$Q$5:$Q$8,0),MATCH(K24,Evalueringskriterier!$R$9:$U$9,0)) -> Meget høj
A25: Test | B25: 5.5 | C25: Sikkerhed Artikel 5, stk. 1, litra f, og artikel 32-34 samt præambelbetragtning nr. 83 og 85-88 | D25: Uopdagede sårbarheder i AI-løsningen som følge af manglende eller mangelfuld sikkerheds- og penetrationstest. | F25: Forventet (4) | H25: Ødelæggende (4) | I25: =INDEX(Evalueringskriterier!$R$5:$U$8,MATCH(H25,Evalueringskriterier!$Q$5:$Q$8,0),MATCH(F25,Evalueringskriterier!$R$9:$U$9,0)) -> Meget høj | K25: Forventet (4) | L25: Ødelæggende (4) | M25: =INDEX(Evalueringskriterier!$R$5:$U$8,MATCH(L25,Evalueringskriterier!$Q$5:$Q$8,0),MATCH(K25,Evalueringskriterier!$R$9:$U$9,0)) -> Meget høj
A26: Test | B26: 5.6 | C26: Dataminimering Artikel 5, stk. 1, litra c | D26: Indsamling af overflødige og/eller irrelevante data som følge manglende review og udvælgelse af, hvilke data der reelt er nødvendige til udvikling og test af AI-løsningen. | F26: Forventet (4) | H26: Ødelæggende (4) | I26: =INDEX(Evalueringskriterier!$R$5:$U$8,MATCH(H26,Evalueringskriterier!$Q$5:$Q$8,0),MATCH(F26,Evalueringskriterier!$R$9:$U$9,0)) -> Meget høj | K26: Forventet (4) | L26: Ødelæggende (4) | M26: =INDEX(Evalueringskriterier!$R$5:$U$8,MATCH(L26,Evalueringskriterier!$Q$5:$Q$8,0),MATCH(K26,Evalueringskriterier!$R$9:$U$9,0)) -> Meget høj
A27: Test | B27: 5.7 | C27: Meningsfyldt menneskeligt review Artikel 13, stk. 2, litra f, artikel 14, stk. 2, litra g, og artikel 15, stk. 1, litra h, samt artikel 22 | D27: Manglende meningsfyldt menneskeligt review som følge af manglende uddannelse og træning af medarbejderne i at fortolke og bestride output, som genereres af AI-løsningen. | F27: Forventet (4) | H27: Ødelæggende (4) | I27: =INDEX(Evalueringskriterier!$R$5:$U$8,MATCH(H27,Evalueringskriterier!$Q$5:$Q$8,0),MATCH(F27,Evalueringskriterier!$R$9:$U$9,0)) -> Meget høj | K27: Forventet (4) | L27: Ødelæggende (4) | M27: =INDEX(Evalueringskriterier!$R$5:$U$8,MATCH(L27,Evalueringskriterier!$Q$5:$Q$8,0),MATCH(K27,Evalueringskriterier!$R$9:$U$9,0)) -> Meget høj
A28: Drift og monitorering
A29: Drift og monitorering | B29: 6.1 | C29: Rimelighed Artikel 5, stk. 1, litra a, og præambelbetragtning nr. 39, 58 samt 60 | D29: Model drift der ikke opdages. | F29: Forventet (4) | H29: Ødelæggende (4) | I29: =INDEX(Evalueringskriterier!$R$5:$U$8,MATCH(H29,Evalueringskriterier!$Q$5:$Q$8,0),MATCH(F29,Evalueringskriterier!$R$9:$U$9,0)) -> Meget høj | K29: Forventet (4) | L29: Ødelæggende (4) | M29: =INDEX(Evalueringskriterier!$R$5:$U$8,MATCH(L29,Evalueringskriterier!$Q$5:$Q$8,0),MATCH(K29,Evalueringskriterier!$R$9:$U$9,0)) -> Meget høj
A30: Drift og monitorering | B30: 6.2 | C30: Rimelighed og sikkerhed Artikel 5, stk. 1, litra a og f, samt betragtning nr. 39, 58 samt 60 og 83 | D30: Misbrug eller forkert brug af AI-løsningen, f.eks. grundet ondsindede insidere eller som følge af manglende kendskab til løsningens muligheder og begrænsninger. | F30: Forventet (4) | H30: Ødelæggende (4) | I30: =INDEX(Evalueringskriterier!$R$5:$U$8,MATCH(H30,Evalueringskriterier!$Q$5:$Q$8,0),MATCH(F30,Evalueringskriterier!$R$9:$U$9,0)) -> Meget høj | K30: Forventet (4) | L30: Ødelæggende (4) | M30: =INDEX(Evalueringskriterier!$R$5:$U$8,MATCH(L30,Evalueringskriterier!$Q$5:$Q$8,0),MATCH(K30,Evalueringskriterier!$R$9:$U$9,0)) -> Meget høj
A31: Drift og monitorering | B31: 6.3 | C31: Sikkerhed Artikel 5, stk. 1, litra f, og artikel 32-34 samt præambelbetragtning nr. 83 og 85-88 | D31: Læk af modelparametre og -beregninger som følge af målrettede angreb (model inversion, membership inference mv.), der kan føre til tab af fortrolighed. | F31: Forventet (4) | H31: Ødelæggende (4) | I31: =INDEX(Evalueringskriterier!$R$5:$U$8,MATCH(H31,Evalueringskriterier!$Q$5:$Q$8,0),MATCH(F31,Evalueringskriterier!$R$9:$U$9,0)) -> Meget høj | K31: Forventet (4) | L31: Ødelæggende (4) | M31: =INDEX(Evalueringskriterier!$R$5:$U$8,MATCH(L31,Evalueringskriterier!$Q$5:$Q$8,0),MATCH(K31,Evalueringskriterier!$R$9:$U$9,0)) -> Meget høj
A32: Drift og monitorering | B32: 6.4 | C32: Sikkerhed Artikel 5, stk. 1, litra f, og artikel 32-34 samt præambelbetragtning nr. 83 og 85-88 | D32: Manipulation af input med henblik at manipulere AI-løsningen, f.eks. fremprovokere et specifikt output, eller ødelægge løsningen. | F32: Forventet (4) | H32: Ødelæggende (4) | I32: =INDEX(Evalueringskriterier!$R$5:$U$8,MATCH(H32,Evalueringskriterier!$Q$5:$Q$8,0),MATCH(F32,Evalueringskriterier!$R$9:$U$9,0)) -> Meget høj | K32: Forventet (4) | L32: Ødelæggende (4) | M32: =INDEX(Evalueringskriterier!$R$5:$U$8,MATCH(L32,Evalueringskriterier!$Q$5:$Q$8,0),MATCH(K32,Evalueringskriterier!$R$9:$U$9,0)) -> Meget høj
A33: Drift og monitorering | B33: 6.5 | C33: Sikkerhed Artikel 5, stk. 1, litra f, og artikel 32-34 samt præambelbetragtning nr. 83 og 85-88 | D33: Utilgængelig eller ødelagt behandlingsaktivitet som følge af, at AI-løsningen, der understøtter aktiviteten, f.eks. grundet hændeligt nedbrud | F33: Forventet (4) | H33: Ødelæggende (4) | I33: =INDEX(Evalueringskriterier!$R$5:$U$8,MATCH(H33,Evalueringskriterier!$Q$5:$Q$8,0),MATCH(F33,Evalueringskriterier!$R$9:$U$9,0)) -> Meget høj | K33: Forventet (4) | L33: Ødelæggende (4) | M33: =INDEX(Evalueringskriterier!$R$5:$U$8,MATCH(L33,Evalueringskriterier!$Q$5:$Q$8,0),MATCH(K33,Evalueringskriterier!$R$9:$U$9,0)) -> Meget høj
A34: Drift og monitorering | B34: 6.6 | C34: Sikkerhed Artikel 5, stk. 1, litra f, og artikel 32-34 samt præambelbetragtning nr. 83 og 85-88 | D34: Denial-of-Service-angreb, der forhindrer brug af AI-løsningen | F34: Forventet (4) | H34: Ødelæggende (4) | I34: =INDEX(Evalueringskriterier!$R$5:$U$8,MATCH(H34,Evalueringskriterier!$Q$5:$Q$8,0),MATCH(F34,Evalueringskriterier!$R$9:$U$9,0)) -> Meget høj | K34: Forventet (4) | L34: Ødelæggende (4) | M34: =INDEX(Evalueringskriterier!$R$5:$U$8,MATCH(L34,Evalueringskriterier!$Q$5:$Q$8,0),MATCH(K34,Evalueringskriterier!$R$9:$U$9,0)) -> Meget høj
A35: Drift og monitorering | B35: 6.7 | C35: Sikkerhed Artikel 5, stk. 1, litra f, og artikel 32-34 samt præambelbetragtning nr. 83 og 85-88 | D35: Usikker håndtering af output, f.eks. AI-løsninger, der bruges som led i kodeskrivning, hvor output ukritisk introduceres i produktionssystemer og giver ondsindede aktører adgang til at afvikle kode i produktionssystemer. | F35: Forventet (4) | H35: Ødelæggende (4) | I35: =INDEX(Evalueringskriterier!$R$5:$U$8,MATCH(H35,Evalueringskriterier!$Q$5:$Q$8,0),MATCH(F35,Evalueringskriterier!$R$9:$U$9,0)) -> Meget høj | K35: Forventet (4) | L35: Ødelæggende (4) | M35: =INDEX(Evalueringskriterier!$R$5:$U$8,MATCH(L35,Evalueringskriterier!$Q$5:$Q$8,0),MATCH(K35,Evalueringskriterier!$R$9:$U$9,0)) -> Meget høj
A36: Drift og monitorering | B36: 6.8 | C36: Dataminimering Artikel 5, stk. 1, litra c, og præambelbetragtning nr. 39 | D36: Model drift, der er forårsaget af, at træningsdata ikke længere er relevant eller tilstrækkeligt. | F36: Forventet (4) | H36: Ødelæggende (4) | I36: =INDEX(Evalueringskriterier!$R$5:$U$8,MATCH(H36,Evalueringskriterier!$Q$5:$Q$8,0),MATCH(F36,Evalueringskriterier!$R$9:$U$9,0)) -> Meget høj | K36: Forventet (4) | L36: Ødelæggende (4) | M36: =INDEX(Evalueringskriterier!$R$5:$U$8,MATCH(L36,Evalueringskriterier!$Q$5:$Q$8,0),MATCH(K36,Evalueringskriterier!$R$9:$U$9,0)) -> Meget høj
A37: Drift og monitorering | B37: 6.9 | C37: Rettigheder Artikel 15-22 og præambelbetragtning nr. 60-71 | D37: Manglende evne til at håndtere indsigelser fra de registrerede vedrørende AI-løsningens output | F37: Forventet (4) | H37: Ødelæggende (4) | I37: =INDEX(Evalueringskriterier!$R$5:$U$8,MATCH(H37,Evalueringskriterier!$Q$5:$Q$8,0),MATCH(F37,Evalueringskriterier!$R$9:$U$9,0)) -> Meget høj | K37: Forventet (4) | L37: Ødelæggende (4) | M37: =INDEX(Evalueringskriterier!$R$5:$U$8,MATCH(L37,Evalueringskriterier!$Q$5:$Q$8,0),MATCH(K37,Evalueringskriterier!$R$9:$U$9,0)) -> Meget høj
A38: Drift og monitorering | B38: 6.10 | C38: Meningsfyldt menneskeligt review Artikel 13, stk. 2, litra f, artikel 14, stk. 2, litra g, og artikel 15, stk. 1, litra h, samt artikel 22 | D38: Manglende meningsfyldt menneskeligt review som følge af automation bias eller manglende forklarlighed. Som følger heraf kan de registrerede blive udsat for unøjagtige eller urimelige afgørelser, som påvirker dem betydeligt. | F38: Forventet (4) | H38: Ødelæggende (4) | I38: =INDEX(Evalueringskriterier!$R$5:$U$8,MATCH(H38,Evalueringskriterier!$Q$5:$Q$8,0),MATCH(F38,Evalueringskriterier!$R$9:$U$9,0)) -> Meget høj | K38: Forventet (4) | L38: Ødelæggende (4) | M38: =INDEX(Evalueringskriterier!$R$5:$U$8,MATCH(L38,Evalueringskriterier!$Q$5:$Q$8,0),MATCH(K38,Evalueringskriterier!$R$9:$U$9,0)) -> Meget høj

Sheet Mitigerende foranstaltninger
A1: Risiko ID | B1: Risikoområde | C1: Mitigerende foranstaltning | D1: Konkrete foranstaltninger
A2: =Risici!A2 -> Afgrænsning af business og use case
A3: =Risici!B3 -> 3.1 | B3: =Risici!C3 -> Ansvarlighed Artikel 5, stk. 2, 35 og 36 samt betragtning nr. 74-77, 84, 89-92, 94 og 95. | C3: Gennemførelse af konsekvensanalyse vedrørende databeskyttelse (DPIA) | D3: Du skal gennemføre en konsekvensanalyse, hvis din behandlingsaktivitet sandsynligvis vil indebære en høj risiko for fysiske personers rettigheder og frihedsrettigheder. Det vil normalt være tilfældet ved udvikling og brug af AI-løsninger.
D4: Du skal, hvis det er relevant, indhente de registreredes synspunkter vedrørende den påtænkte behandlingsaktivitet.
D5: Hvis du identificerer høje risici, som du ikke kan mitigere, skal du høre Datatilsynet, inden du begynder behandlingsaktiviteten.
D6: For at identificere de relevante risici i AI-løsningen, bør du som led i konsekvensanalysen konsultere de enheder i organisationen, som vil være involveret i projektet. Det omfatter bl.a. udviklere, jura og compliance, samt de(n) enhed(er), hvor løsningen skal bruges.
D7: Du bør rådføre dig med domæneeksperter som kan rådgive dig om de relevante risici, som du skal identificere og mitigere.
A8: =Risici!B4 -> 3.2 | B8: =Risici!C4 -> Ansvarlighed Artikel 5, stk. 2, og 24 samt betragtning nr. 39 and 74 | C8: Tildeling af tekniske og operationelle roller og anvisning af klar retning for brugen af AI-løsningen. | D8: Du bør udpege en proces- eller systemejer for at sikre, at ansvaret for AI-løsningen forankres i organisationen.
D9: Du bør fastsætte operationelle procedurer og politikker for at understøtte korrekt brug af AI-løsningen samt udarbejde vejledninger, som anviser medarbejderne en korrekt brug af AI-løsningen.
A10: =Risici!B5 -> 3.3 | B10: =Risici!C5 -> Formålsbegrænsning og lovlighed Artikel 5, stk. 1, litra b, artikel 6, stk. 1 og 4, og 30 samt betragtning nr. 39 og 50. | C10: Dokumentation af (i) hvorfra data hidrører, (ii) hvert formål med behandling af persondata på hvert trin af AI-livscyklussen, (iii) vurdering om formålene er forenelige med det oprindelige formål og (iv) fastsættelse af intervaller for review af, om formålene forbliver forenelige. | D10: Du bør etablere procedurer for data proviniens og data governance. Som led heri bør du gennemføre datastrømsanalyse, og afdække hvilke oplysninger der tilgår, bliver behandlet i og udgår fra AI-løsningen for at sikre behandlingen er lovlig og forenelig med det oprindelige formål.
A11: =Risici!B6 -> 3.4 | B11: =Risici!C6 -> Princippet om rimelighed Artikel 5, stk. 1, litra a, og præambelbetragtning nr. 39, 40 samt 58 | C11: Vurdering og dokumentation af de forskellige måder, hvorpå AI-løsningen kan resultere i urimelige udfald, og hvilke passende tekniske og organisatoriske foranstaltninger der implementeres for kontinuerligt at mitigere disse risici. | D11: Du bør sikre dig, at vurderingen gennemføres af tilstrækkeligt kvalificerede medarbejdere. Det kan være nødvendigt at vurderingen gennemføres som en tværfaglig indsats ved f.eks. data scientists, der samarbejder med juridiske rådgivere mv.
D12: Du bør sikre dig, at vurderingen i første omgang har fokus på de forventede udfald for de registrerede, der påvirkes af behandlingsaktiviteten.
D13: Du bør rådføre dig med relevante interessenter for at kortlægge de risici, som din behandlingsaktivitet kan medføre.
A14: =Risici!B7 -> 3.5 | B14: =Risici!C7 -> Gennemsigtighed Artikel 5, stk. 1, litra a, og 12-15 samt præambelbetragtning nr. 60-62 | C14: Vurdering og dokumentation af kravene til forklarlighed og gennemsigtighed under hensyntagen til, hvordan AI-løsningen vil blive brugt i det pågældende domæne eller sektor. | D14: Du bør vurdere, hvilke forventninger de registrerede har til, hvor forklarlig AI-løsningens output skal være. Det kan f.eks. baseres på tidligere tilsvarende forklaringer i lignende AI-løsninger. Det kan også ske ved at undersøge forklaringer i andre sektorer, f.eks. hvad forventningerne er til forklarlighed i sundhedssektoren eller i forsikringsbranchen.
D15: For at beslutte hvor fyldestgørende din forklaring skal være, bør du vurdere, hvor forståeligt det nuværende output af AI-løsningen er.
A16: =Risici!B8 -> 3.6 | B16: =Risici!C8 -> Dataminimering Artikel 5, stk. 1, litra c, samt betragtning nr. 39 | C16: Dokumentation af, hvilket datasæt der vil blive brugt til at udvikle AI-løsningen, og vurdering af, hvorvidt datasættet er rigtigt, tilstrækkeligt, relevant og begrænset til det nødvendige. | D16: Du bør sikre dig, at det jævnligt evalueres, hvilke persondata der er nødvendige og hvorfor. Du kan fastsætte retningslinjer for, hvordan og hvor hyppigt evalueringen skal ske.
D17: Du bør vurdere, hvilke privatlivsfremmende teknologier der kan være passende for den pågældende AI-løsning for at sikre dataminimering.
D18: Du kan rådføre dig med domæneeksperter for at sikre, at persondata, som du forventer at indsamle, er passende og tilstrækkelige.
A19: =Risici!B9 -> 3.7 | B19: =Risici!C9 -> Sikkerhed Artikel 5, stk. 1, litra f, og artikel 32-34 samt præambelbetragtning nr. 83 og 85-88 | C19: Vurdering og dokumentation af de tredjepartsmodeller, der bruges til udvikling af AI-løsningen. | D19: Du skal forhåndsundersøge leverandørerne og udviklerne af de tredjepartsmodeller, som skal anvendes til udvikling af løsningen, herunder vilkår og eventuelle privatlivspolitikker. Brug kun pålidelige leverandører.
D20: Du bør sikre, at tredjepartsmodellerne er testet, og at sikkerheden er auditeret.
D21: Du bør løbende overvåge leverandørens eventuelle vilkår og sikkerhedsaudits for at sikre, at tredjepartsmodellen fortsat er robust, og at modellen ikke har ændret sig væsentligt fra udgangspunktet.
D22: Du bør implementere en passende politik for opdatering og patching af AI-løsningen, der er baseret på tredjepartsmodellen, for at sikre, at den nyeste udgave af modellen eller API'et benyttes.
A23: =Risici!B10 -> 3.8 | B23: =Risici!C10 -> Rettigheder Artikel 15-22 og præambelbetragtning nr. 60-71 | C23: Dokumentation af, hvordan udøvelsen af de registreredes rettigheder vil blive faciliteret gennem hele AI-løsningens livscyklus. | D23: Du bør organisere workshops i organisationen for at sikre, at udviklerne er klar over, at der skal stilles funktionalitet til rådighed som tillader organisationen at håndtere anmodninger fra de registrerede om udøvelsen af deres rettigheder.
D24: Du kan gennemføre brugertests for at få feedback om, hvor lettilgængeligt og letforståeligt de informationer, som du skal give de registrerede, er.
D25: Du skal sikre, at der er adgang til meningsfyldt menneskeligt review, når AI-løsningen træffer fuldautomatiske afgørelser, som har retsvirkning eller på tilsvarende vis betydeligt påvirker de registrerede.
A26: =Risici!A11 -> Udvikling
A27: =Risici!B12 -> 4.1 | B27: =Risici!C12 -> Rimelighed Artikel 5, stk. 1, litra a, og præambelbetragtning nr. 39, 58 samt 60 | C27: Vurdering og dokumentation af, hvilke data der er nødvendige for at sikre et repræsentativt, pålideligt og relevant træningsdatasæt. | D27: Du skal rense og justere datasæt, som du skal bruge til udvikling for at sikre, at data er repræsentative, pålidelige og relevante.
D28: Du bør indregne risikoen for tidligere diskrimination.
D29: Du bør overveje, om du skal indsamle specifikke datapunkter til brug for biasanalyse.
A30: =Risici!B13 -> 4.2 | B30: =Risici!C13 -> Rimelighed Artikel 5, stk. 1, litra a, og præambelbetragtning nr. 39, 58 samt 60 | C30: Vurdering og dokumentation af, hvilke datakilder eller features, som ikke bør behandles på grund af risikoen for direkte eller indirekte diskrimination. Samtidig bør det vurderes, om visse af disse data eller features desuagtet skal indsamles til brug for bias analyse. | D30: Du bør overveje, om du har behov for at behandle yderligere data for at gennemføre biasanalyse, og om du har behov for at lave labels for data, som du allerede har, eller om du skal indsamle yderligere data.
D31: Du bør overveje, om visse data skal indsamles eller features skal indgå som led i din biasanalyse.
D32: Hvis du er nødt til at behandle andre kategorier af persondata til brug for biasanalyse, end de typer der allerede indgår i trænings- og testdata, skal du identificere et behandlingsgrundlag for disse data.
D33: Du bør fastsætte kriterier for mærkning som er lette at forstå, omfatter beskrivelser af og eksempler for alle mærker. Kriterierne bør også omfatte "gråzone"-tilfælde.
A34: =Risici!B14 -> 4.3 | B34: =Risici!C14 -> Rimelighed Artikel 5, stk. 1, litra a, og præambelbetragtning nr. 39, 58 samt 60 | C34: Fastlæggelse og dokumentation af klare kriterier og procedurer for mærkning af træningsdata | D34: Du bør udarbejde vejledninger for mærkning og annotering.
D35: Du bør sikre, at medarbejderne med ansvaret for mærkning og annotering er tilstrækkeligt kvalificerede, og at sammensætningen af medarbejderne er tilstrækkeligt mangfoldig.
D36: Du kan rådføre dig med relevante interessenter eller interesseorganisationer for at definere mærkningskriterierne.
D37: Processen for mærkning og annotering bør indeholde procedurer for kvalitetssikring, herunder af subjektive og objektive mærker. Ved subjektive mærker forstås tilfælde, hvor der ikke findes et korrekt mærke, og mærket tildeles skønsmæssigt af medarbejderen. Ved objektive mærker forstås tilfælde, hvor der findes et korrekt mærke, men medarbejderen er ikke bekendt med, hvordan det anvendes. Processen bør også omfatte, at flere medarbejdere mærker samme datapunkter uafhængigt af hinanden med henblik på sammenligning.
D38: Du kan udarbejde statistikker for, hvor ofte medarbejderne der forestår mærkningen, er enige.
D39: Hvis du benytter dig af automatisk mærkning, bør du fastsætte procedurer for kvalitetssikring heraf.
A40: =Risici!B15 -> 4.4 | B40: =Risici!C15 -> Rimelighed Artikel 5, stk. 1, litra a og c, og præambelbetragtning nr. 39, 58 samt 60 | C40: Vurdering og dokumentation af, i hvilket omfang modellen er tilbøjelig til overfitting | D40: Du skal fjerne features som sandsynligvis kan medføre overfitting.
...

Sheet Interessentinddragelse
A1: Interessentinddragelse
B2: Databeskyttelsesrådgiverens synspunkter Databeskyttelsesforordningens artikel 35, stk. 2 | I2: [Angiv databeskyttelsesrådgiverens synspunkter og bemærkninger til den gennemførte konsekvensanalyse.]
B4: Registreredes (eller deres repræsentanters) synspunkter Databeskyttelsesforordningens artikel 35, stk. 9 | I4: [Hvis det er relevant, skal de registrerede eller deres repræsentanters synspunkter om den planlagte behandlingsaktivitet indhentes. Hvis de registrerede eller deres repræsentanters synspunkter ikke indhentes, bør begrundelsen for dette fravalg dokumenteres.]
B6: Høring af Datatilsynet Databeskyttelsesforordningens artikel 36 | I6: [Hvis konsekvensanalysen viser, at behandlingen indebærer høj risiko – til trods for foranstaltninger for at nedbringe risikoen – skal Datatilsynet høres, inden behandlingsaktiviteten iværksættes. Angiv, hvis relevant, at Datatilsynet er blevet hørt, hvornår, og hvilke eventuelle bemærkninger I har modtaget.]
A8: Ledelsesgodkendelse
B9: Ledelsens synspunkter og godkendelse
A11: Ansvarlig for konsekvensanalyse
B12: Konsekvensanalysen ajourføres løbende af
